Workbook
Name Area_day: #REF!
Name In_MBA: #REF!
Name Khac_MBA: #REF!
Name Load_MVAr: [1]MVAr!$C:$T
Name Load_MW: [1]MW!$C:$V
Name Load_Shunt: [1]Shunt!$C:$T
Name maday: #REF!
Name madayamp: #REF!
Name Out_MBA: #REF!
Name TEN: [2]Sheet2!$A$1:$C$65536

Sheet Owners
A1: owner_code | B1: owner_name_en | C1: owner_name_vi
A2: 1
A3: 10 | B3: PTC_1 | C3: Truyền tải điện 1
A4: 20 | B4: PTC_2 | C4: Truyền tải điện 2
A5: 30 | B5: PTC_3 | C5: Truyền tải điện 3
A6: 40 | B6: PTC_4 | C6: Truyền tải điện 4
A7: 50 | B7: 500_KV | C7: Lưới 500kV
A8: 100 | B8: NPC | C8: TCT Điện Lực Miền Bắc
A9: 200 | B9: SPC | C9: TCT Điện Lực Miền Nam
A10: 300 | B10: CPC | C10: TCT Điện Lực Miền Trung
A11: 355
A12: 358
A13: 400 | B13: HA_NOI | C13: TCT Điện Lực Hà Nội
A14: 450
A15: 500 | B15: HCM | C15: TCT Điện Lực TP.HCM
A16: 600 | B16: KH_BAC | C16: Khách hàng 110kV Bắc
A17: 700 | B17: KH_NAM | C17: Khách hàng 110kV Nam
A18: 701
A19: 702
A20: 703
A21: 706
A22: 709
A23: 710
A24: 800 | B24: KH_TRUNG | C24: Khách hàng 110kV Trung
A25: 1000 | B25: THUY_DIEN | C25: Thủy điện
A26: 2000 | B26: ND_THAN | C26: Nhiệt điện than
A27: 2100 | B27: ND SINH KHOI | C27: Nhiệt điện sinh khối
A28: 3000 | B28: TBK_GT | C28: Tuabin khí (dùng khí)
A29: 3100 | B29: TBK_ST | C29: Tuabin khí (đuôi hơi)
A30: 4000 | B30: TB_DAU_GT | C30: Tuabin dầu (dùng khí)
A31: 4100 | B31: TB_DAU_ST | C31: Tuabin dầu (đuôi hơi)
A32: 4200 | B32: ND_DAU | C32: Nhiệt điện dầu (đốt dầu)
A33: 5000 | B33: TDN | C33: Thủy điện nhỏ (<30MW)
A34: 6000 | B34: DIESEL | C34: Nguồn Diesel
A35: 6100 | B35: NGUON_KHAC | C35: Nguồn khác
... A40: 9000 | B40: CAMPUCHIA | C40: Nhập khẩu Campuchia

Sheet Zones
A1: Sym | B1: zone_code | C1: zone_name_en | D1: zone_name_vi
A2: B1 | B2: 150 | C2: HA_NOI | D2: Hà Nội
A3: B2 | B3: 160 | C3: HAI_PHONG | D3: Hải Phòng
A4: B23 | B4: 170 | C4: NINH_BINH | D4: Ninh Bình
A5: B4 | B5: 104 | C5: PHU_THO | D5: Phú Thọ
A6: B5 | B6: 105 | C6: QUANG_NINH | D6: Quảng Ninh
A7: B6 | B7: 106 | C7: THAI_NGUYEN | D7: Thái Nguyên
A8: B27 | B8: 127 | C8: BAC_NINH | D8: Bắc Ninh
A9: B9 | B9: 109 | C9: THANH_HOA | D9: Thanh Hóa
A10: B28 | B10: 128 | C10: HUNG_YEN | D10: Hưng Yên
A11: B20 | B11: 120 | C11: LAO_CAI | D11: Lào Cai
A12: B13 | B12: 113 | C12: LANG_SON | D12: Lạng Sơn
A13: B14 | B13: 114 | C13: TUYEN_QUANG | D13: Tuyên Quang
... A21: TQ | B21: 7000 | C21: TRUNG_QUOC | D21: Trung Quốc
B22: 10 | C22: PTC_1 | D22: Truyền tải 1
B23: 30 | C23: PTC_3
B24: 40 | C24: PTC_4
B25: 50 | C25: 500_KV
B26: 351 | C26: TAY_NINH
B27: 354 | C27: LAM_DONG
B28: 360 | C28: CAN_THO
B29: 363 | C29: AN_GIANG
B30: 365 | C30: VINH_LONG
B31: 367 | C31: DONG_THAP
B32: 369 | C32: CA_MAU
B33: 400 | C33: TP_HCM
B34: 450 | C34: DONG_NAI
... B41: 710 | C41: DAK_LAK
B42: 1600 | C42: KH_BAC | D42: KH_Bắc
B43: 9000 | C43: CAMPUCHIA | D43: Campuchia

Sheet Buses
A1: bus_code | B1: bus_name_vi | C1: TBA_SCADA | D1: Sym | E1: Sym_Tran | F1: Note | G1: Type | H1: Name | I1: Type2 | J1: zone_code | K1: owner_code | M1: Type | N1: Type2 | O1: Type3
A2: 1000 | B2: T110 Đông Anh | C2: TBA 110kV Đông Anh | D2: B1 | E2: E1.1 | F2: =IF(E2<>"","Đã VH","Quy hoạch điện VIII") | G2: =LEFT(B2,FIND(" ",B2,1)-1) | H2: =TRIM(RIGHT(B2,LEN(B2)-FIND(" ",B2,1))) | I2: =_xlfn.XLOOKUP(Table2[[#This Row],[Type]],Table5[Type],Table5[Type2]) | J2: =_xlfn.XLOOKUP(Table2[[#This Row],[Sym]],Zones!$A$2:$A$21,Zones!$B$2:$B$21) | M2: T110 | N2: TBA | O2: TBA 110kV
A3: 1001 | B3: T110 Gia Lâm | C3: TBA 110kV Gia Lâm | D3: B1 | E3: E1.2 | F3: =IF(E3<>"","Đã VH","Quy hoạch điện VIII") | G3: =LEFT(B3,FIND(" ",B3,1)-1) | H3: =TRIM(RIGHT(B3,LEN(B3)-FIND(" ",B3,1))) | I3: =_xlfn.XLOOKUP(Table2[[#This Row],[Type]],Table5[Type],Table5[Type2]) | J3: =_xlfn.XLOOKUP(Table2[[#This Row],[Sym]],Zones!$A$2:$A$21,Zones!$B$2:$B$21) | M3: T220 | N3: TBA | O3: TBA 220kV
A4: 1002 | B4: T220 Mai Động | C4: TBA 220kV Mai Động | D4: B1 | E4: E1.3 | F4: =IF(E4<>"","Đã VH","Quy hoạch điện VIII") | G4: =LEFT(B4,FIND(" ",B4,1)-1) | H4: =TRIM(RIGHT(B4,LEN(B4)-FIND(" ",B4,1))) | I4: =_xlfn.XLOOKUP(Table2[[#This Row],[Type]],Table5[Type],Table5[Type2]) | J4: =_xlfn.XLOOKUP(Table2[[#This Row],[Sym]],Zones!$A$2:$A$21,Zones!$B$2:$B$21) | M4: T500 | N4: TBA | O4: TBA 500kV
A5: 1003 | B5: T220 Hà Đông | C5: TBA 220kV Hà Đông | D5: B1 | E5: E1.4 | F5: =IF(E5<>"","Đã VH","Quy hoạch điện VIII") | G5: =LEFT(B5,FIND(" ",B5,1)-1) | H5: =TRIM(RIGHT(B5,LEN(B5)-FIND(" ",B5,1))) | I5: =_xlfn.XLOOKUP(Table2[[#This Row],[Type]],Table5[Type],Table5[Type2]) | J5: =_xlfn.XLOOKUP(Table2[[#This Row],[Sym]],Zones!$A$2:$A$21,Zones!$B$2:$B$21) | M5: ĐR | N5: NLTT
A6: 1004 | B6: T110 Thượng Đình | C6: TBA 110kV Thượng Đình | D6: B1 | E6: E1.5 | F6: =IF(E6<>"","Đã VH","Quy hoạch điện VIII") | G6: =LEFT(B6,FIND(" ",B6,1)-1) | H6: =TRIM(RIGHT(B6,LEN(B6)-FIND(" ",B6,1))) | I6: =_xlfn.XLOOKUP(Table2[[#This Row],[Type]],Table5[Type],Table5[Type2]) | J6: =_xlfn.XLOOKUP(Table2[[#This Row],[Sym]],Zones!$A$2:$A$21,Zones!$B$2:$B$21) | M6: NĐ | N6: NĐ
A7: 1005 | B7: T220 Chèm | C7: TBA 220kV Chèm | D7: B1 | E7: E1.6 | F7: =IF(E7<>"","Đã VH","Quy hoạch điện VIII") | G7: =LEFT(B7,FIND(" ",B7,1)-1) | H7: =TRIM(RIGHT(B7,LEN(B7)-FIND(" ",B7,1))) | I7: =_xlfn.XLOOKUP(Table2[[#This Row],[Type]],Table5[Type],Table5[Type2]) | J7: =_xlfn.XLOOKUP(Table2[[#This Row],[Sym]],Zones!$A$2:$A$21,Zones!$B$2:$B$21) | M7: LNG | N7: LNG
A8: 1006 | B8: T110 Sơn Tây | C8: TBA 110kV Sơn Tây | D8: B1 | E8: E1.7 | F8: =IF(E8<>"","Đã VH","Quy hoạch điện VIII") | G8: =LEFT(B8,FIND(" ",B8,1)-1) | H8: =TRIM(RIGHT(B8,LEN(B8)-FIND(" ",B8,1))) | I8: =_xlfn.XLOOKUP(Table2[[#This Row],[Type]],Table5[Type],Table5[Type2]) | J8: =_xlfn.XLOOKUP(Table2[[#This Row],[Sym]],Zones!$A$2:$A$21,Zones!$B$2:$B$21) | M8: TĐ | N8: TĐ | O8: NM TĐN
A9: 1007 | B9: T110 Yên Phụ | C9: TBA 110kV Yên Phụ | D9: B1 | E9: E1.8 | F9: =IF(E9<>"","Đã VH","Quy hoạch điện VIII") | G9: =LEFT(B9,FIND(" ",B9,1)-1) | H9: =TRIM(RIGHT(B9,LEN(B9)-FIND(" ",B9,1))) | I9: =_xlfn.XLOOKUP(Table2[[#This Row],[Type]],Table5[Type],Table5[Type2]) | J9: =_xlfn.XLOOKUP(Table2[[#This Row],[Sym]],Zones!$A$2:$A$21,Zones!$B$2:$B$21) | M9: ĐMT | N9: NLTT
A10: 1008 | B10: T110 Nghĩa Đô | C10: TBA 110kV Nghĩa Đô | D10: B1 | E10: E1.9 | F10: =IF(E10<>"","Đã VH","Quy hoạch điện VIII") | G10: =LEFT(B10,FIND(" ",B10,1)-1) | H10: =TRIM(RIGHT(B10,LEN(B10)-FIND(" ",B10,1))) | I10: =_xlfn.XLOOKUP(Table2[[#This Row],[Type]],Table5[Type],Table5[Type2]) | J10: =_xlfn.XLOOKUP(Table2[[#This Row],[Sym]],Zones!$A$2:$A$21,Zones!$B$2:$B$21) | M10: SKMĐ | N10: NLTT
A11: 1009 | B11: T110 Văn Điển | C11: TBA 110kV Văn Điển | D11: B1 | E11: E1.10 | F11: =IF(E11<>"","Đã VH","Quy hoạch điện VIII") | G11: =LEFT(B11,FIND(" ",B11,1)-1) | H11: =TRIM(RIGHT(B11,LEN(B11)-FIND(" ",B11,1))) | I11: =_xlfn.XLOOKUP(Table2[[#This Row],[Type]],Table5[Type],Table5[Type2]) | J11: =_xlfn.XLOOKUP(Table2[[#This Row],[Sym]],Zones!$A$2:$A$21,Zones!$B$2:$B$21) | M11: TĐTN | N11: NLTT
A12: 1010 | B12: T220 Thành Công | C12: TBA 220kV Thành Công | D12: B1 | E12: E1.11 | F12: =IF(E12<>"","Đã VH","Quy hoạch điện VIII") | G12: =LEFT(B12,FIND(" ",B12,1)-1) | H12: =TRIM(RIGHT(B12,LEN(B12)-FIND(" ",B12,1))) | I12: =_xlfn.XLOOKUP(Table2[[#This Row],[Type]],Table5[Type],Table5[Type2]) | J12: =_xlfn.XLOOKUP(Table2[[#This Row],[Sym]],Zones!$A$2:$A$21,Zones!$B$2:$B$21) | M12: Formosa | N12: NĐ
A13: 1011 | B13: T110 Trần Hưng Đạo | C13: TBA 110kV Trần Hưng Đạo | D13: B1 | E13: E1.12 | F13: =IF(E13<>"","Đã VH","Quy hoạch điện VIII") | G13: =LEFT(B13,FIND(" ",B13,1)-1) | H13: =TRIM(RIGHT(B13,LEN(B13)-FIND(" ",B13,1))) | I13: =_xlfn.XLOOKUP(Table2[[#This Row],[Type]],Table5[Type],Table5[Type2]) | J13: =_xlfn.XLOOKUP(Table2[[#This Row],[Sym]],Zones!$A$2:$A$21,Zones!$B$2:$B$21) | M13: ĐSK | N13: NLTT
A14: 1012 | B14: T110 Phương Liệt | C14: TBA 110kV Phương Liệt | D14: B1 | E14: E1.13 | F14: =IF(E14<>"","Đã VH","Quy hoạch điện VIII") | G14: =LEFT(B14,FIND(" ",B14,1)-1) | H14: =TRIM(RIGHT(B14,LEN(B14)-FIND(" ",B14,1))) | I14: =_xlfn.XLOOKUP(Table2[[#This Row],[Type]],Table5[Type],Table5[Type2]) | J14: =_xlfn.XLOOKUP(Table2[[#This Row],[Sym]],Zones!$A$2:$A$21,Zones!$B$2:$B$21) | M14: ĐG | N14: NLTT
A15: 1013 | B15: T110 Giám | C15: TBA 110kV Giám | D15: B1 | E15: E1.14 | F15: =IF(E15<>"","Đã VH","Quy hoạch điện VIII") | G15: =LEFT(B15,FIND(" ",B15,1)-1) | H15: =TRIM(RIGHT(B15,LEN(B15)-FIND(" ",B15,1))) | I15: =_xlfn.XLOOKUP(Table2[[#This Row],[Type]],Table5[Type],Table5[Type2]) | J15: =_xlfn.XLOOKUP(Table2[[#This Row],[Sym]],Zones!$A$2:$A$21,Zones!$B$2:$B$21)
A16: 1014 | B16: T110 Sài Đồng | C16: TBA 110kV Sài Đồng | D16: B1 | E16: E1.15 | F16: =IF(E16<>"","Đã VH","Quy hoạch điện VIII") | G16: =LEFT(B16,FIND(" ",B16,1)-1) | H16: =TRIM(RIGHT(B16,LEN(B16)-FIND(" ",B16,1))) | I16: =_xlfn.XLOOKUP(Table2[[#This Row],[Type]],Table5[Type],Table5[Type2]) | J16: =_xlfn.XLOOKUP(Table2[[#This Row],[Sym]],Zones!$A$2:$A$21,Zones!$B$2:$B$21)
A17: 1015 | B17: T110 Nội Bài | C17: TBA 110kV Nội Bài | D17: B1 | E17: E1.16 | F17: =IF(E17<>"","Đã VH","Quy hoạch điện VIII") | G17: =LEFT(B17,FIND(" ",B17,1)-1) | H17: =TRIM(RIGHT(B17,LEN(B17)-FIND(" ",B17,1))) | I17: =_xlfn.XLOOKUP(Table2[[#This Row],[Type]],Table5[Type],Table5[Type2]) | J17: =_xlfn.XLOOKUP(Table2[[#This Row],[Sym]],Zones!$A$2:$A$21,Zones!$B$2:$B$21)
A18: 1016 | B18: T110 Bắc Thăng Long | C18: TBA 110kV Bắc Thăng Long | D18: B1 | E18: E1.17 | F18: =IF(E18<>"","Đã VH","Quy hoạch điện VIII") | G18: =LEFT(B18,FIND(" ",B18,1)-1) | H18: =TRIM(RIGHT(B18,LEN(B18)-FIND(" ",B18,1))) | I18: =_xlfn.XLOOKUP(Table2[[#This Row],[Type]],Table5[Type],Table5[Type2]) | J18: =_xlfn.XLOOKUP(Table2[[#This Row],[Sym]],Zones!$A$2:$A$21,Zones!$B$2:$B$21)
A19: 1017 | B19: T110 Bờ Hồ | C19: TBA 110kV Bờ Hồ | D19: B1 | E19: E1.18 | F19: =IF(E19<>"","Đã VH","Quy hoạch điện VIII") | G19: =LEFT(B19,FIND(" ",B19,1)-1) | H19: =TRIM(RIGHT(B19,LEN(B19)-FIND(" ",B19,1))) | I19: =_xlfn.XLOOKUP(Table2[[#This Row],[Type]],Table5[Type],Table5[Type2]) | J19: =_xlfn.XLOOKUP(Table2[[#This Row],[Sym]],Zones!$A$2:$A$21,Zones!$B$2:$B$21)
A20: 1018 | B20: T220 Sóc Sơn | C20: TBA 220kV Sóc Sơn | D20: B1 | E20: E1.19 | F20: =IF(E20<>"","Đã VH","Quy hoạch điện VIII") | G20: =LEFT(B20,FIND(" ",B20,1)-1) | H20: =TRIM(RIGHT(B20,LEN(B20)-FIND(" ",B20,1))) | I20: =_xlfn.XLOOKUP(Table2[[#This Row],[Type]],Table5[Type],Table5[Type2]) | J20: =_xlfn.XLOOKUP(Table2[[#This Row],[Sym]],Zones!$A$2:$A$21,Zones!$B$2:$B$21)
A21: 1019 | B21: T110 Thanh Xuân | C21: TBA 110kV Thanh Xuân | D21: B1 | E21: E1.20 | F21: =IF(E21<>"","Đã VH","Quy hoạch điện VIII") | G21: =LEFT(B21,FIND(" ",B21,1)-1) | H21: =TRIM(RIGHT(B21,LEN(B21)-FIND(" ",B21,1))) | I21: =_xlfn.XLOOKUP(Table2[[#This Row],[Type]],Table5[Type],Table5[Type2]) | J21: =_xlfn.XLOOKUP(Table2[[#This Row],[Sym]],Zones!$A$2:$A$21,Zones!$B$2:$B$21)
A22: 1020 | B22: T110 Nhật Tân | C22: TBA 110kV Nhật Tân | D22: B1 | E22: E1.21 | F22: =IF(E22<>"","Đã VH","Quy hoạch điện VIII") | G22: =LEFT(B22,FIND(" ",B22,1)-1) | H22: =TRIM(RIGHT(B22,LEN(B22)-FIND(" ",B22,1))) | I22: =_xlfn.XLOOKUP(Table2[[#This Row],[Type]],Table5[Type],Table5[Type2]) | J22: =_xlfn.XLOOKUP(Table2[[#This Row],[Sym]],Zones!$A$2:$A$21,Zones!$B$2:$B$21)
A23: 1021 | B23: T110 Thanh Nhàn | C23: TBA 110kV Thanh Nhàn | D23: B1 | E23: E1.22 | F23: =IF(E23<>"","Đã VH","Quy hoạch điện VIII") | G23: =LEFT(B23,FIND(" ",B23,1)-1) | H23: =TRIM(RIGHT(B23,LEN(B23)-FIND(" ",B23,1))) | I23: =_xlfn.XLOOKUP(Table2[[#This Row],[Type]],Table5[Type],Table5[Type2]) | J23: =_xlfn.XLOOKUP(Table2[[#This Row],[Sym]],Zones!$A$2:$A$21,Zones!$B$2:$B$21)
A24: 1022 | B24: T220 Vân Trì | C24: TBA 220kV Vân Trì | D24: B1 | E24: E1.23 | F24: =IF(E24<>"","Đã VH","Quy hoạch điện VIII") | G24: =LEFT(B24,FIND(" ",B24,1)-1) | H24: =TRIM(RIGHT(B24,LEN(B24)-FIND(" ",B24,1))) | I24: =_xlfn.XLOOKUP(Table2[[#This Row],[Type]],Table5[Type],Table5[Type2]) | J24: =_xlfn.XLOOKUP(Table2[[#This Row],[Sym]],Zones!$A$2:$A$21,Zones!$B$2:$B$21)
A25: 1023 | B25: T110 Hải Bối | C25: TBA 110kV Hải Bối | D25: B1 | E25: E1.24 | F25: =IF(E25<>"","Đã VH","Quy hoạch điện VIII") | G25: =LEFT(B25,FIND(" ",B25,1)-1) | H25: =TRIM(RIGHT(B25,LEN(B25)-FIND(" ",B25,1))) | I25: =_xlfn.XLOOKUP(Table2[[#This Row],[Type]],Table5[Type],Table5[Type2]) | J25: =_xlfn.XLOOKUP(Table2[[#This Row],[Sym]],Zones!$A$2:$A$21,Zones!$B$2:$B$21)
A26: 1024 | B26: T110 Mỹ Đình | C26: TBA 110kV Mỹ Đình | D26: B1 | E26: E1.25 | F26: =IF(E26<>"","Đã VH","Quy hoạch điện VIII") | G26: =LEFT(B26,FIND(" ",B26,1)-1) | H26: =TRIM(RIGHT(B26,LEN(B26)-FIND(" ",B26,1))) | I26: =_xlfn.XLOOKUP(Table2[[#This Row],[Type]],Table5[Type],Table5[Type2]) | J26: =_xlfn.XLOOKUP(Table2[[#This Row],[Sym]],Zones!$A$2:$A$21,Zones!$B$2:$B$21)
... A72: 1071 | B72: T500 Đông Anh | C72: TBA 500kV Đông Anh | D72: B1 | E72: T500 Đông Anh | F72: =IF(E72<>"","Đã VH","Quy hoạch điện VIII") | G72: =LEFT(B72,FIND(" ",B72,1)-1) | H72: =TRIM(RIGHT(B72,LEN(B72)-FIND(" ",B72,1))) | I72: =_xlfn.XLOOKUP(Table2[[#This Row],[Type]],Table5[Type],Table5[Type2]) | J72: =_xlfn.XLOOKUP(Table2[[#This Row],[Sym]],Zones!$A$2:$A$21,Zones!$B$2:$B$21)
A73: 1072 | B73: T500 Long Biên | C73: TBA 500kV Long Biên | D73: B1 | F73: =IF(E73<>"","Đã VH","Quy hoạch điện VIII") | G73: =LEFT(B73,FIND(" ",B73,1)-1) | H73: =TRIM(RIGHT(B73,LEN(B73)-FIND(" ",B73,1))) | I73: =_xlfn.XLOOKUP(Table2[[#This Row],[Type]],Table5[Type],Table5[Type2]) | J73: =_xlfn.XLOOKUP(Table2[[#This Row],[Sym]],Zones!$A$2:$A$21,Zones!$B$2:$B$21)
A74: 1073 | B74: T500 Sơn Tây | C74: TBA 500kV Sơn Tây | D74: B1 | F74: =IF(E74<>"","Đã VH","Quy hoạch điện VIII") | G74: =LEFT(B74,FIND(" ",B74,1)-1) | H74: =TRIM(RIGHT(B74,LEN(B74)-FIND(" ",B74,1))) | I74: =_xlfn.XLOOKUP(Table2[[#This Row],[Type]],Table5[Type],Table5[Type2]) | J74: =_xlfn.XLOOKUP(Table2[[#This Row],[Sym]],Zones!$A$2:$A$21,Zones!$B$2:$B$21)
A75: 1074 | B75: T500 Nam Hà Nội | C75: TBA 500kV Nam Hà Nội | D75: B1 | F75: =IF(E75<>"","Đã VH","Quy hoạch điện VIII") | G75: =LEFT(B75,FIND(" ",B75,1)-1) | H75: =TRIM(RIGHT(B75,LEN(B75)-FIND(" ",B75,1))) | I75: =_xlfn.XLOOKUP(Table2[[#This Row],[Type]],Table5[Type],Table5[Type2]) | J75: =_xlfn.XLOOKUP(Table2[[#This Row],[Sym]],Zones!$A$2:$A$21,Zones!$B$2:$B$21)
A76: 1075 | B76: T220 Long Biên | C76: TBA 220 KV Long Biên | D76: B1 | E76: E1.45 | F76: =IF(E76<>"","Đã VH","Quy hoạch điện VIII") | G76: =LEFT(B76,FIND(" ",B76,1)-1) | H76: =TRIM(RIGHT(B76,LEN(B76)-FIND(" ",B76,1))) | I76: =_xlfn.XLOOKUP(Table2[[#This Row],[Type]],Table5[Type],Table5[Type2]) | J76: =_xlfn.XLOOKUP(Table2[[#This Row],[Sym]],Zones!$A$2:$A$21,Zones!$B$2:$B$21) | AH76: Đã sửa từ dashboard (TBA 220kV Long Biên ➔ TBA 220 KV Long Biên )
A77: 1076 | B77: T500 Tây Hà Nội | C77: TBA 500kV Tây Hà Nội | D77: B1 | E77: T500 Tây Hà Nội | F77: =IF(E77<>"","Đã VH","Quy hoạch điện VIII") | G77: =LEFT(B77,FIND(" ",B77,1)-1) | H77: =TRIM(RIGHT(B77,LEN(B77)-FIND(" ",B77,1))) | I77: =_xlfn.XLOOKUP(Table2[[#This Row],[Type]],Table5[Type],Table5[Type2]) | J77: =_xlfn.XLOOKUP(Table2[[#This Row],[Sym]],Zones!$A$2:$A$21,Zones!$B$2:$B$21)
A78: 1077 | B78: T220 Đông Anh | C78: TBA 220kV Đông Anh | D78: B1 | F78: =IF(E78<>"","Đã VH","Quy hoạch điện VIII") | G78: =LEFT(B78,FIND(" ",B78,1)-1) | H78: =TRIM(RIGHT(B78,LEN(B78)-FIND(" ",B78,1))) | I78: =_xlfn.XLOOKUP(Table2[[#This Row],[Type]],Table5[Type],Table5[Type2]) | J78: =_xlfn.XLOOKUP(Table2[[#This Row],[Sym]],Zones!$A$2:$A$21,Zones!$B$2:$B$21)
A79: 1078 | B79: T220 Văn Điển | C79: TBA 220kV Văn Điển | D79: B1 | F79: =IF(E79<>"","Đã VH","Quy hoạch điện VIII") | G79: =LEFT(B79,FIND(" ",B79,1)-1) | H79: =TRIM(RIGHT(B79,LEN(B79)-FIND(" ",B79,1))) | I79: =_xlfn.XLOOKUP(Table2[[#This Row],[Type]],Table5[Type],Table5[Type2]) | J79: =_xlfn.XLOOKUP(Table2[[#This Row],[Sym]],Zones!$A$2:$A$21,Zones!$B$2:$B$21)
A80: 1079 | B80: T220 Mê Linh | C80: TBA 220kV Mê Linh | D80: B1 | F80: =IF(E80<>"","Đã VH","Quy hoạch điện VIII") | G80: =LEFT(B80,FIND(" ",B80,1)-1) | H80: =TRIM(RIGHT(B80,LEN(B80)-FIND(" ",B80,1))) | I80: =_xlfn.XLOOKUP(Table2[[#This Row],[Type]],Table5[Type],Table5[Type2]) | J80: =_xlfn.XLOOKUP(Table2[[#This Row],[Sym]],Zones!$A$2:$A$21,Zones!$B$2:$B$21)
A81: 1080 | B81: T220 Ứng Hòa | C81: TBA 220kV Ứng Hòa | D81: B1 | F81: =IF(E81<>"","Đã VH","Quy hoạch điện VIII") | G81: =LEFT(B81,FIND(" ",B81,1)-1) | H81: =TRIM(RIGHT(B81,LEN(B81)-FIND(" ",B81,1))) | I81: =_xlfn.XLOOKUP(Table2[[#This Row],[Type]],Table5[Type],Table5[Type2]) | J81: =_xlfn.XLOOKUP(Table2[[#This Row],[Sym]],Zones!$A$2:$A$21,Zones!$B$2:$B$21)
A82: 1081 | B82: T220 Đại Mỗ | C82: TBA 220kV Đại Mỗ | D82: B1 | F82: =IF(E82<>"","Đã VH","Quy hoạch điện VIII") | G82: =LEFT(B82,FIND(" ",B82,1)-1) | H82: =TRIM(RIGHT(B82,LEN(B82)-FIND(" ",B82,1))) | I82: =_xlfn.XLOOKUP(Table2[[#This Row],[Type]],Table5[Type],Table5[Type2]) | J82: =_xlfn.XLOOKUP(Table2[[#This Row],[Sym]],Zones!$A$2:$A$21,Zones!$B$2:$B$21)
A83: 1082 | B83: T220 Đông Anh 2 | C83: TBA 220kV Đông Anh 2 | D83: B1 | F83: =IF(E83<>"","Đã VH","Quy hoạch điện VIII") | G83: =LEFT(B83,FIND(" ",B83,1)-1) | H83: =TRIM(RIGHT(B83,LEN(B83)-FIND(" ",B83,1))) | I83: =_xlfn.XLOOKUP(Table2[[#This Row],[Type]],Table5[Type],Table5[Type2]) | J83: =_xlfn.XLOOKUP(Table2[[#This Row],[Sym]],Zones!$A$2:$A$21,Zones!$B$2:$B$21)
A84: 1083 | B84: T220 Sóc Sơn 2 | C84: TBA 220kV Sóc Sơn 2 | D84: B1 | F84: =IF(E84<>"","Đã VH","Quy hoạch điện VIII") | G84: =LEFT(B84,FIND(" ",B84,1)-1) | H84: =TRIM(RIGHT(B84,LEN(B84)-FIND(" ",B84,1))) | I84: =_xlfn.XLOOKUP(Table2[[#This Row],[Type]],Table5[Type],Table5[Type2]) | J84: =_xlfn.XLOOKUP(Table2[[#This Row],[Sym]],Zones!$A$2:$A$21,Zones!$B$2:$B$21)
A85: 1084 | B85: T220 Long Biên 2 | C85: TBA 220kV Long Biên 2 | D85: B1 | F85: =IF(E85<>"","Đã VH","Quy hoạch điện VIII") | G85: =LEFT(B85,FIND(" ",B85,1)-1) | H85: =TRIM(RIGHT(B85,LEN(B85)-FIND(" ",B85,1))) | I85: =_xlfn.XLOOKUP(Table2[[#This Row],[Type]],Table5[Type],Table5[Type2]) | J85: =_xlfn.XLOOKUP(Table2[[#This Row],[Sym]],Zones!$A$2:$A$21,Zones!$B$2:$B$21)
...
